<?xml version="1.0" encoding="utf-8"?>
<mujoco model="cabinet">
    <asset>
        <texture file="../textures/red-wood.png" type="cube" name="red-wood"/>
        <material name="red-wood"  reflectance="1.0" shininess="1.0" specular="0.4" texrepeat="1 1" texture="red-wood" texuniform="true"/>
    </asset>
  <worldbody>
      <body>
          <body name="object" pos="0.0 0 0">
              <body name="base" pos="0 0 0" quat="1 0 0 0">
                  <inertial pos="0 0 -0.0375" quat="0.5 0.5 0.5 0.5" mass="2.0" diaginertia="0.5 0.5 0.5" />
                  <geom material="red-wood" pos="0.0 0 -0.0375" size="0.1 0.095 0.0375" group="1" type="box" mass=".05"/>

                  <geom material="red-wood" pos="-0.099 0 0.0375" size="0.001 0.093 0.0375" group="1" type="box" mass=".05"/>
                  <geom material="red-wood" pos="0 0.094 0.0375" size="0.1 0.001 0.0375" group="1" type="box" mass=".05"/>
                  <geom material="red-wood" pos="0 -0.094 0.0375" size="0.1 0.001 0.0375" group="1" type="box" mass=".05"/>
                  <geom material="red-wood" pos="0 0 0.074" size="0.1 0.093 0.001" group="1" type="box" mass=".05"/>
                  <geom material="red-wood" pos="0 0 0.001" size="0.1 0.093 0.001" group="1" type="box" mass=".05"/>

                  <body name="drawer_link" pos="0 0 0">
                          <inertial pos="0 0 0.0375" quat="0.5 0.5 0.5 0.5" mass="0.2" diaginertia="0.5 0.5 0.5" />
                    
                      <joint type="slide" range="0 0.14" axis="1 0 0"
                      name="goal_slidey" pos="0 0 0" damping="10.0"/>
                      
                      <geom material="red-wood" pos="0.099 0 0.0375" size="0.001 0.093 0.0355" group="1" type="box" mass=".1"/>
                      <geom material="red-wood" pos="0.0 0.092 0.032" size="0.098 0.001 0.03" group="1" type="box" mass=".04"/>
                      <geom material="red-wood" pos="0.0 -0.092 0.032" size="0.098 0.001 0.03" group="1" type="box" mass=".04"/>
                      <geom material="red-wood" pos="0.0 0 0.003" size="0.098 0.091 0.001" group="1" type="box" mass=".04"/>
                  </body>
              </body>
          </body>
          <site name="bottom_site" pos="0 0 -0.075" rgba="0 0 0 0" size="0.005"/>
          <site name="top_site" pos="0 0 0.075" rgba="0 0 0 0" size="0.005"/>
          <site name="horizontal_radius_site" pos="0.3 0 0" rgba="0 0 0 0" size="0.1"/>
      </body>
    </worldbody>
</mujoco>